Workbook

Sheet Master Dashboard
A2: Executive Habit & Performance Master Dashboard | F2: Multi-Year Executive Suite (2026 – 2030)
A3: "Long-term consistency trumps short-term intensity. Track, review, and elevate."
A4: 🏛️ Quarterly Hub | C4: 📚 Habit Library
A5: GLOBAL SUCCESS RATE | C5: ALL-TIME CHECKS | E5: TOTAL TARGET DAYS | G5: PEAK MONTH ON RECORD | I5: GLOBAL AVG SLEEP
A6: =AVERAGEIF(E19:E70, ">0") | C6: =SUM(D19:D70) | E6: =SUM(C19:C70) | G6: =INDEX(A19:A70, MATCH(MAX(E19:E70), E19:E70, 0)) | I6: =IFERROR(TEXT(AVERAGEIF(G19:G70, ">0"), "0.0") & " hrs", "-")
A9: Overall Execution Rate | C9: Total Done Checks Logged | E9: All Commitments Made | G9: Highest Consistency Month | I9: Multi-Year Sleep Average
A11: ⚡ ONE-CLICK MONTH NAVIGATOR (CLICK ANY MONTH TO JUMP DIRECTLY)
A12: Year 2026: | B12: Sep | C12: Oct | D12: Nov | E12: Dec
A13: Year 2027: | B13: Jan | C13: Feb | D13: Mar | E13: Apr | F13: May | G13: Jun | H13: Jul | I13: Aug | J13: Sep | K13: Oct | L13: Nov | M13: Dec
A14: Year 2028: | B14: Jan | C14: Feb | D14: Mar | E14: Apr | F14: May | G14: Jun | H14: Jul | I14: Aug | J14: Sep | K14: Oct | L14: Nov | M14: Dec
A15: Year 2029: | B15: Jan | C15: Feb | D15: Mar | E15: Apr | F15: May | G15: Jun | H15: Jul | I15: Aug | J15: Sep | K15: Oct | L15: Nov | M15: Dec
A16: Year 2030: | B16: Jan | C16: Feb | D16: Mar | E16: Apr | F16: May | G16: Jun | H16: Jul | I16: Aug | J16: Sep | K16: Oct | L16: Nov | M16: Dec
A18: Month & Year | B18: Active Habits | C18: Target Days | D18: Done Checks | E18: Success % | F18: Perfect Days | G18: Avg Sleep (hrs) | H18: Best Week | I18: Top Life Domain | J18: Direct Link
A19: Sep 2026 | B19: ='Sep 2026'!E92 | C19: ='Sep 2026'!G92 | D19: ='Sep 2026'!I92 | E19: ='Sep 2026'!K92 | F19: ='Sep 2026'!M92 | G19: ='Sep 2026'!O92 | H19: ='Sep 2026'!Q92 | I19: ='Sep 2026'!T92 | J19: Jump ↗
A20: Oct 2026 | B20: ='Oct 2026'!E92 | C20: ='Oct 2026'!G92 | D20: ='Oct 2026'!I92 | E20: ='Oct 2026'!K92 | F20: ='Oct 2026'!M92 | G20: ='Oct 2026'!O92 | H20: ='Oct 2026'!Q92 | I20: ='Oct 2026'!T92 | J20: Jump ↗
A21: Nov 2026 | B21: ='Nov 2026'!E92 | C21: ='Nov 2026'!G92 | D21: ='Nov 2026'!I92 | E21: ='Nov 2026'!K92 | F21: ='Nov 2026'!M92 | G21: ='Nov 2026'!O92 | H21: ='Nov 2026'!Q92 | I21: ='Nov 2026'!T92 | J21: Jump ↗
A22: Dec 2026 | B22: ='Dec 2026'!E92 | C22: ='Dec 2026'!G92 | D22: ='Dec 2026'!I92 | E22: ='Dec 2026'!K92 | F22: ='Dec 2026'!M92 | G22: ='Dec 2026'!O92 | H22: ='Dec 2026'!Q92 | I22: ='Dec 2026'!T92 | J22: Jump ↗
A23: Jan 2027 | B23: ='Jan 2027'!E92 | C23: ='Jan 2027'!G92 | D23: ='Jan 2027'!I92 | E23: ='Jan 2027'!K92 | F23: ='Jan 2027'!M92 | G23: ='Jan 2027'!O92 | H23: ='Jan 2027'!Q92 | I23: ='Jan 2027'!T92 | J23: Jump ↗
A24: Feb 2027 | B24: ='Feb 2027'!E92 | C24: ='Feb 2027'!G92 | D24: ='Feb 2027'!I92 | E24: ='Feb 2027'!K92 | F24: ='Feb 2027'!M92 | G24: ='Feb 2027'!O92 | H24: ='Feb 2027'!Q92 | I24: ='Feb 2027'!T92 | J24: Jump ↗
A25: Mar 2027 | B25: ='Mar 2027'!E92 | C25: ='Mar 2027'!G92 | D25: ='Mar 2027'!I92 | E25: ='Mar 2027'!K92 | F25: ='Mar 2027'!M92 | G25: ='Mar 2027'!O92 | H25: ='Mar 2027'!Q92 | I25: ='Mar 2027'!T92 | J25: Jump ↗
A26: Apr 2027 | B26: ='Apr 2027'!E92 | C26: ='Apr 2027'!G92 | D26: ='Apr 2027'!I92 | E26: ='Apr 2027'!K92 | F26: ='Apr 2027'!M92 | G26: ='Apr 2027'!O92 | H26: ='Apr 2027'!Q92 | I26: ='Apr 2027'!T92 | J26: Jump ↗
A27: May 2027 | B27: ='May 2027'!E92 | C27: ='May 2027'!G92 | D27: ='May 2027'!I92 | E27: ='May 2027'!K92 | F27: ='May 2027'!M92 | G27: ='May 2027'!O92 | H27: ='May 2027'!Q92 | I27: ='May 2027'!T92 | J27: Jump ↗
A28: Jun 2027 | B28: ='Jun 2027'!E92 | C28: ='Jun 2027'!G92 | D28: ='Jun 2027'!I92 | E28: ='Jun 2027'!K92 | F28: ='Jun 2027'!M92 | G28: ='Jun 2027'!O92 | H28: ='Jun 2027'!Q92 | I28: ='Jun 2027'!T92 | J28: Jump ↗
A29: Jul 2027 | B29: ='Jul 2027'!E92 | C29: ='Jul 2027'!G92 | D29: ='Jul 2027'!I92 | E29: ='Jul 2027'!K92 | F29: ='Jul 2027'!M92 | G29: ='Jul 2027'!O92 | H29: ='Jul 2027'!Q92 | I29: ='Jul 2027'!T92 | J29: Jump ↗
A30: Aug 2027 | B30: ='Aug 2027'!E92 | C30: ='Aug 2027'!G92 | D30: ='Aug 2027'!I92 | E30: ='Aug 2027'!K92 | F30: ='Aug 2027'!M92 | G30: ='Aug 2027'!O92 | H30: ='Aug 2027'!Q92 | I30: ='Aug 2027'!T92 | J30: Jump ↗
A31: Sep 2027 | B31: ='Sep 2027'!E92 | C31: ='Sep 2027'!G92 | D31: ='Sep 2027'!I92 | E31: ='Sep 2027'!K92 | F31: ='Sep 2027'!M92 | G31: ='Sep 2027'!O92 | H31: ='Sep 2027'!Q92 | I31: ='Sep 2027'!T92 | J31: Jump ↗
A32: Oct 2027 | B32: ='Oct 2027'!E92 | C32: ='Oct 2027'!G92 | D32: ='Oct 2027'!I92 | E32: ='Oct 2027'!K92 | F32: ='Oct 2027'!M92 | G32: ='Oct 2027'!O92 | H32: ='Oct 2027'!Q92 | I32: ='Oct 2027'!T92 | J32: Jump ↗
A33: Nov 2027 | B33: ='Nov 2027'!E92 | C33: ='Nov 2027'!G92 | D33: ='Nov 2027'!I92 | E33: ='Nov 2027'!K92 | F33: ='Nov 2027'!M92 | G33: ='Nov 2027'!O92 | H33: ='Nov 2027'!Q92 | I33: ='Nov 2027'!T92 | J33: Jump ↗
A34: Dec 2027 | B34: ='Dec 2027'!E92 | C34: ='Dec 2027'!G92 | D34: ='Dec 2027'!I92 | E34: ='Dec 2027'!K92 | F34: ='Dec 2027'!M92 | G34: ='Dec 2027'!O92 | H34: ='Dec 2027'!Q92 | I34: ='Dec 2027'!T92 | J34: Jump ↗
A35: Jan 2028 | B35: ='Jan 2028'!E92 | C35: ='Jan 2028'!G92 | D35: ='Jan 2028'!I92 | E35: ='Jan 2028'!K92 | F35: ='Jan 2028'!M92 | G35: ='Jan 2028'!O92 | H35: ='Jan 2028'!Q92 | I35: ='Jan 2028'!T92 | J35: Jump ↗
A36: Feb 2028 | B36: ='Feb 2028'!E92 | C36: ='Feb 2028'!G92 | D36: ='Feb 2028'!I92 | E36: ='Feb 2028'!K92 | F36: ='Feb 2028'!M92 | G36: ='Feb 2028'!O92 | H36: ='Feb 2028'!Q92 | I36: ='Feb 2028'!T92 | J36: Jump ↗
A37: Mar 2028 | B37: ='Mar 2028'!E92 | C37: ='Mar 2028'!G92 | D37: ='Mar 2028'!I92 | E37: ='Mar 2028'!K92 | F37: ='Mar 2028'!M92 | G37: ='Mar 2028'!O92 | H37: ='Mar 2028'!Q92 | I37: ='Mar 2028'!T92 | J37: Jump ↗
A38: Apr 2028 | B38: ='Apr 2028'!E92 | C38: ='Apr 2028'!G92 | D38: ='Apr 2028'!I92 | E38: ='Apr 2028'!K92 | F38: ='Apr 2028'!M92 | G38: ='Apr 2028'!O92 | H38: ='Apr 2028'!Q92 | I38: ='Apr 2028'!T92 | J38: Jump ↗
A39: May 2028 | B39: ='May 2028'!E92 | C39: ='May 2028'!G92 | D39: ='May 2028'!I92 | E39: ='May 2028'!K92 | F39: ='May 2028'!M92 | G39: ='May 2028'!O92 | H39: ='May 2028'!Q92 | I39: ='May 2028'!T92 | J39: Jump ↗
A40: Jun 2028 | B40: ='Jun 2028'!E92 | C40: ='Jun 2028'!G92 | D40: ='Jun 2028'!I92 | E40: ='Jun 2028'!K92 | F40: ='Jun 2028'!M92 | G40: ='Jun 2028'!O92 | H40: ='Jun 2028'!Q92 | I40: ='Jun 2028'!T92 | J40: Jump ↗
A41: Jul 2028 | B41: ='Jul 2028'!E92 | C41: ='Jul 2028'!G92 | D41: ='Jul 2028'!I92 | E41: ='Jul 2028'!K92 | F41: ='Jul 2028'!M92 | G41: ='Jul 2028'!O92 | H41: ='Jul 2028'!Q92 | I41: ='Jul 2028'!T92 | J41: Jump ↗
A42: Aug 2028 | B42: ='Aug 2028'!E92 | C42: ='Aug 2028'!G92 | D42: ='Aug 2028'!I92 | E42: ='Aug 2028'!K92 | F42: ='Aug 2028'!M92 | G42: ='Aug 2028'!O92 | H42: ='Aug 2028'!Q92 | I42: ='Aug 2028'!T92 | J42: Jump ↗
A43: Sep 2028 | B43: ='Sep 2028'!E92 | C43: ='Sep 2028'!G92 | D43: ='Sep 2028'!I92 | E43: ='Sep 2028'!K92 | F43: ='Sep 2028'!M92 | G43: ='Sep 2028'!O92 | H43: ='Sep 2028'!Q92 | I43: ='Sep 2028'!T92 | J43: Jump ↗
A44: Oct 2028 | B44: ='Oct 2028'!E92 | C44: ='Oct 2028'!G92 | D44: ='Oct 2028'!I92 | E44: ='Oct 2028'!K92 | F44: ='Oct 2028'!M92 | G44: ='Oct 2028'!O92 | H44: ='Oct 2028'!Q92 | I44: ='Oct 2028'!T92 | J44: Jump ↗
A45: Nov 2028 | B45: ='Nov 2028'!E92 | C45: ='Nov 2028'!G92 | D45: ='Nov 2028'!I92 | E45: ='Nov 2028'!K92 | F45: ='Nov 2028'!M92 | G45: ='Nov 2028'!O92 | H45: ='Nov 2028'!Q92 | I45: ='Nov 2028'!T92 | J45: Jump ↗
...

Sheet Quarterly Hub
A2: Quarterly Sprints, OKRs & Performance Review Hub | F2: 17 Quarters Sprint Milestone Tracker (2026 – 2030)
A3: "What gets measured quarterly gets mastered annually. Align 90-day sprints with daily execution."
A4: 🏠 Master Dashboard | C4: 📚 Habit Library
A6: Quarter | B6: Year | C6: Months Included | D6: Checks Done | E6: Target Days | F6: Quarter Success % | G6: Avg Sleep (hrs) | H6: Consistency Tier | I6: Direct Link
A7: Q4 2026 | B7: 2026 | C7: Sep – Dec | D7: ='Sep 2026'!I92 + 'Oct 2026'!I92 + 'Nov 2026'!I92 + 'Dec 2026'!I92 | E7: ='Sep 2026'!G92 + 'Oct 2026'!G92 + 'Nov 2026'!G92 + 'Dec 2026'!G92 | F7: =IF(E7>0, D7/E7, 0) | G7: =IFERROR(AVERAGE('Sep 2026'!O92, 'Oct 2026'!O92, 'Nov 2026'!O92, 'Dec 2026'!O92), 0) | H7: =IF(F7>=0.85, "🏆 Elite Master", IF(F7>=0.7, "⭐ Consistent", "📈 Building")) | I7: Open ↗
A8: Q1 2027 | B8: 2027 | C8: Jan – Mar | D8: ='Jan 2027'!I92 + 'Feb 2027'!I92 + 'Mar 2027'!I92 | E8: ='Jan 2027'!G92 + 'Feb 2027'!G92 + 'Mar 2027'!G92 | F8: =IF(E8>0, D8/E8, 0) | G8: =IFERROR(AVERAGE('Jan 2027'!O92, 'Feb 2027'!O92, 'Mar 2027'!O92), 0) | H8: =IF(F8>=0.85, "🏆 Elite Master", IF(F8>=0.7, "⭐ Consistent", "📈 Building")) | I8: Open ↗
A9: Q2 2027 | B9: 2027 | C9: Apr – Jun | D9: ='Apr 2027'!I92 + 'May 2027'!I92 + 'Jun 2027'!I92 | E9: ='Apr 2027'!G92 + 'May 2027'!G92 + 'Jun 2027'!G92 | F9: =IF(E9>0, D9/E9, 0) | G9: =IFERROR(AVERAGE('Apr 2027'!O92, 'May 2027'!O92, 'Jun 2027'!O92), 0) | H9: =IF(F9>=0.85, "🏆 Elite Master", IF(F9>=0.7, "⭐ Consistent", "📈 Building")) | I9: Open ↗
A10: Q3 2027 | B10: 2027 | C10: Jul – Sep | D10: ='Jul 2027'!I92 + 'Aug 2027'!I92 + 'Sep 2027'!I92 | E10: ='Jul 2027'!G92 + 'Aug 2027'!G92 + 'Sep 2027'!G92 | F10: =IF(E10>0, D10/E10, 0) | G10: =IFERROR(AVERAGE('Jul 2027'!O92, 'Aug 2027'!O92, 'Sep 2027'!O92), 0) | H10: =IF(F10>=0.85, "🏆 Elite Master", IF(F10>=0.7, "⭐ Consistent", "📈 Building")) | I10: Open ↗
A11: Q4 2027 | B11: 2027 | C11: Oct – Dec | D11: ='Oct 2027'!I92 + 'Nov 2027'!I92 + 'Dec 2027'!I92 | E11: ='Oct 2027'!G92 + 'Nov 2027'!G92 + 'Dec 2027'!G92 | F11: =IF(E11>0, D11/E11, 0) | G11: =IFERROR(AVERAGE('Oct 2027'!O92, 'Nov 2027'!O92, 'Dec 2027'!O92), 0) | H11: =IF(F11>=0.85, "🏆 Elite Master", IF(F11>=0.7, "⭐ Consistent", "📈 Building")) | I11: Open ↗
A12: Q1 2028 | B12: 2028 | C12: Jan – Mar | D12: ='Jan 2028'!I92 + 'Feb 2028'!I92 + 'Mar 2028'!I92 | E12: ='Jan 2028'!G92 + 'Feb 2028'!G92 + 'Mar 2028'!G92 | F12: =IF(E12>0, D12/E12, 0) | G12: =IFERROR(AVERAGE('Jan 2028'!O92, 'Feb 2028'!O92, 'Mar 2028'!O92), 0) | H12: =IF(F12>=0.85, "🏆 Elite Master", IF(F12>=0.7, "⭐ Consistent", "📈 Building")) | I12: Open ↗
A13: Q2 2028 | B13: 2028 | C13: Apr – Jun | D13: ='Apr 2028'!I92 + 'May 2028'!I92 + 'Jun 2028'!I92 | E13: ='Apr 2028'!G92 + 'May 2028'!G92 + 'Jun 2028'!G92 | F13: =IF(E13>0, D13/E13, 0) | G13: =IFERROR(AVERAGE('Apr 2028'!O92, 'May 2028'!O92, 'Jun 2028'!O92), 0) | H13: =IF(F13>=0.85, "🏆 Elite Master", IF(F13>=0.7, "⭐ Consistent", "📈 Building")) | I13: Open ↗
A14: Q3 2028 | B14: 2028 | C14: Jul – Sep | D14: ='Jul 2028'!I92 + 'Aug 2028'!I92 + 'Sep 2028'!I92 | E14: ='Jul 2028'!G92 + 'Aug 2028'!G92 + 'Sep 2028'!G92 | F14: =IF(E14>0, D14/E14, 0) | G14: =IFERROR(AVERAGE('Jul 2028'!O92, 'Aug 2028'!O92, 'Sep 2028'!O92), 0) | H14: =IF(F14>=0.85, "🏆 Elite Master", IF(F14>=0.7, "⭐ Consistent", "📈 Building")) | I14: Open ↗
A15: Q4 2028 | B15: 2028 | C15: Oct – Dec | D15: ='Oct 2028'!I92 + 'Nov 2028'!I92 + 'Dec 2028'!I92 | E15: ='Oct 2028'!G92 + 'Nov 2028'!G92 + 'Dec 2028'!G92 | F15: =IF(E15>0, D15/E15, 0) | G15: =IFERROR(AVERAGE('Oct 2028'!O92, 'Nov 2028'!O92, 'Dec 2028'!O92), 0) | H15: =IF(F15>=0.85, "🏆 Elite Master", IF(F15>=0.7, "⭐ Consistent", "📈 Building")) | I15: Open ↗
A16: Q1 2029 | B16: 2029 | C16: Jan – Mar | D16: ='Jan 2029'!I92 + 'Feb 2029'!I92 + 'Mar 2029'!I92 | E16: ='Jan 2029'!G92 + 'Feb 2029'!G92 + 'Mar 2029'!G92 | F16: =IF(E16>0, D16/E16, 0) | G16: =IFERROR(AVERAGE('Jan 2029'!O92, 'Feb 2029'!O92, 'Mar 2029'!O92), 0) | H16: =IF(F16>=0.85, "🏆 Elite Master", IF(F16>=0.7, "⭐ Consistent", "📈 Building")) | I16: Open ↗
A17: Q2 2029 | B17: 2029 | C17: Apr – Jun | D17: ='Apr 2029'!I92 + 'May 2029'!I92 + 'Jun 2029'!I92 | E17: ='Apr 2029'!G92 + 'May 2029'!G92 + 'Jun 2029'!G92 | F17: =IF(E17>0, D17/E17, 0) | G17: =IFERROR(AVERAGE('Apr 2029'!O92, 'May 2029'!O92, 'Jun 2029'!O92), 0) | H17: =IF(F17>=0.85, "🏆 Elite Master", IF(F17>=0.7, "⭐ Consistent", "📈 Building")) | I17: Open ↗
A18: Q3 2029 | B18: 2029 | C18: Jul – Sep | D18: ='Jul 2029'!I92 + 'Aug 2029'!I92 + 'Sep 2029'!I92 | E18: ='Jul 2029'!G92 + 'Aug 2029'!G92 + 'Sep 2029'!G92 | F18: =IF(E18>0, D18/E18, 0) | G18: =IFERROR(AVERAGE('Jul 2029'!O92, 'Aug 2029'!O92, 'Sep 2029'!O92), 0) | H18: =IF(F18>=0.85, "🏆 Elite Master", IF(F18>=0.7, "⭐ Consistent", "📈 Building")) | I18: Open ↗
A19: Q4 2029 | B19: 2029 | C19: Oct – Dec | D19: ='Oct 2029'!I92 + 'Nov 2029'!I92 + 'Dec 2029'!I92 | E19: ='Oct 2029'!G92 + 'Nov 2029'!G92 + 'Dec 2029'!G92 | F19: =IF(E19>0, D19/E19, 0) | G19: =IFERROR(AVERAGE('Oct 2029'!O92, 'Nov 2029'!O92, 'Dec 2029'!O92), 0) | H19: =IF(F19>=0.85, "🏆 Elite Master", IF(F19>=0.7, "⭐ Consistent", "📈 Building")) | I19: Open ↗
A20: Q1 2030 | B20: 2030 | C20: Jan – Mar | D20: ='Jan 2030'!I92 + 'Feb 2030'!I92 + 'Mar 2030'!I92 | E20: ='Jan 2030'!G92 + 'Feb 2030'!G92 + 'Mar 2030'!G92 | F20: =IF(E20>0, D20/E20, 0) | G20: =IFERROR(AVERAGE('Jan 2030'!O92, 'Feb 2030'!O92, 'Mar 2030'!O92), 0) | H20: =IF(F20>=0.85, "🏆 Elite Master", IF(F20>=0.7, "⭐ Consistent", "📈 Building")) | I20: Open ↗
A21: Q2 2030 | B21: 2030 | C21: Apr – Jun | D21: ='Apr 2030'!I92 + 'May 2030'!I92 + 'Jun 2030'!I92 | E21: ='Apr 2030'!G92 + 'May 2030'!G92 + 'Jun 2030'!G92 | F21: =IF(E21>0, D21/E21, 0) | G21: =IFERROR(AVERAGE('Apr 2030'!O92, 'May 2030'!O92, 'Jun 2030'!O92), 0) | H21: =IF(F21>=0.85, "🏆 Elite Master", IF(F21>=0.7, "⭐ Consistent", "📈 Building")) | I21: Open ↗
A22: Q3 2030 | B22: 2030 | C22: Jul – Sep | D22: ='Jul 2030'!I92 + 'Aug 2030'!I92 + 'Sep 2030'!I92 | E22: ='Jul 2030'!G92 + 'Aug 2030'!G92 + 'Sep 2030'!G92 | F22: =IF(E22>0, D22/E22, 0) | G22: =IFERROR(AVERAGE('Jul 2030'!O92, 'Aug 2030'!O92, 'Sep 2030'!O92), 0) | H22: =IF(F22>=0.85, "🏆 Elite Master", IF(F22>=0.7, "⭐ Consistent", "📈 Building")) | I22: Open ↗
A23: Q4 2030 | B23: 2030 | C23: Oct – Dec | D23: ='Oct 2030'!I92 + 'Nov 2030'!I92 + 'Dec 2030'!I92 | E23: ='Oct 2030'!G92 + 'Nov 2030'!G92 + 'Dec 2030'!G92 | F23: =IF(E23>0, D23/E23, 0) | G23: =IFERROR(AVERAGE('Oct 2030'!O92, 'Nov 2030'!O92, 'Dec 2030'!O92), 0) | H23: =IF(F23>=0.85, "🏆 Elite Master", IF(F23>=0.7, "⭐ Consistent", "📈 Building")) | I23: Open ↗
A26: 🎯 90-DAY SPRINT OBJECTIVES & KEY RESULTS (OKRs)
A27: Sprint 1: Foundation & Baseline (Q4 2026) Objective: Solidify uninterrupted morning & evening anchors. • KR1: Maintain ≥80% on 3 non-negotiable health protocols. • KR2: Nightly sleep average ≥ 7.2 hours. • KR3: 0 missed check-ins on Sunday reviews. | D27: Sprint 2: Deep Work & Vitality (Q1 2027) Objective: Scale cognitive stamina & physical output. • KR1: Log 45 deep work sprints (90 min). • KR2: Complete 10,000 steps on 80% of days. • KR3: Zero sugar on weekdays throughout sprint. | G27: Sprint 3: Mental Mastery & Finance (Q2 2027) Objective: Eliminate digital clutter & optimize savings. • KR1: Zero phone 1st hour on 25+ days/month. • KR2: 100% daily expense logging consistency. • KR3: Read 6 complete high-leverage books.
A33: 🎓 HABIT EVOLUTION & GRADUATION BOARD (AUTOMATIC HABITS VS NEW PROTOCOLS)
A34: Habit Protocol Name | C34: Domain | D34: Month Introduced | E34: Quarter Graduated | F34: Status / Milestone | H34: Long-Term Impact
A35: Morning Sunlight 10m | C35: Health & Fitness | D35: Sep 2026 | E35: Q4 2026 | F35: 🎓 Graduated (Second Nature) | H35: Circadian rhythm fully automated upon waking
A36: Hydration 1L on Waking | C36: Health & Fitness | D36: Sep 2026 | E36: Q4 2026 | F36: 🎓 Graduated (Second Nature) | H36: Zero mental effort required; glass pre-set at night
A37: 90-Min Deep Work Block | C37: Career & Focus | D37: Oct 2026 | E37: Q1 2027 | F37: ⚡ In Progress (Active Sprint) | H37: Calendar protected from 9:00 - 10:30 AM daily
A38: Read 20 Pages Non-Fiction | C38: Mindset | D38: Nov 2026 | E38: Q2 2027 | F38: ⚡ In Progress (Active Sprint) | H38: Book stays on nightstand; 15 books read to date
A39: Daily Expense Logging | C39: Finance | D39: Jan 2027 | E39: Q2 2027 | F39: 🌱 Planned Sprint Protocol | H39: App shortcut configured on home screen

Sheet Habit Library
A2: Habit Mastery Playbook & Curated Protocol Vault | E2: 60+ Science-Backed Protocols & Atomic Habits Framework
A3: "You do not rise to the level of your goals. You fall to the level of your systems." — James Clear
A4: 🏠 Master Dashboard | C4: 🏛️ Quarterly Hub
A6: S.No. | B6: Life Domain | C6: Protocol Name | D6: Recommended Target | E6: Optimal Timing | F6: Habit Cue / Trigger | G6: Expected Transformation / ROI
A7: 1 | B7: Health & Fitness | C7: Huberman Morning Sunlight (10m) | D7: 25-30 days | E7: Within 30m of waking | F7: Right after opening bedroom blinds | G7: Sets circadian rhythm, cortisol spike & nighttime melatonin
A8: 2 | B8: Health & Fitness | C8: Electrolyte Hydration (1L on waking) | D8: 30 days | E8: First thing morning | F8: Placed on bedside table before sleep | G8: Reverses nighttime dehydration & jumpstarts metabolism
A9: 3 | B9: Health & Fitness | C9: Zone 2 Aerobic Cardio (45m) | D9: 16-20 days | E9: Morning / Early afternoon | F9: Gym clothes laid out the night before | G9: Mitochondrial density, endurance & metabolic longevity
A10: 4 | B10: Health & Fitness | C10: 10,000 Daily Steps | D10: 25-30 days | E10: Spread throughout day | F10: Take phone calls while walking outdoors | G10: Non-exercise activity thermogenesis (NEAT) & cardiovascular health
A11: 5 | B11: Health & Fitness | C11: Resistance Training (Compound Lifts) | D11: 16-18 days | E11: Late morning / 4-6 PM | F11: Gym bag in car / office entryway | G11: Muscle protein synthesis, bone density & metabolic rate
A12: 6 | B12: Health & Fitness | C12: Cold Exposure (2-3m cold shower) | D12: 20-25 days | E12: Post-morning workout / waking | F12: Finish warm shower with cold tap handle | G12: 250% prolonged dopamine elevation & cold-shock resilience
A13: 7 | B13: Health & Fitness | C13: Post-Meal 10-Minute Walk | D13: 25-30 days | E13: Immediately after lunch/dinner | F13: Put on walking shoes right after putting plate away | G13: Blunts blood glucose spikes by up to 35% & aids digestion
A14: 8 | B14: Health & Fitness | C14: No Screens 60m Before Bedtime | D14: 25-30 days | E14: 1 hour before sleep | F14: Phone placed on charger in kitchen/bathroom | G14: Prevents blue light melatonin suppression & improves sleep architecture
A15: 9 | B15: Health & Fitness | C15: Nightly Mobility & Spine Drills | D15: 20-25 days | E15: Evening wind-down | F15: Yoga mat unrolled beside bed | G15: Alleviates sitting stiffness, decompression & joint flexibility
A16: 10 | B16: Health & Fitness | C16: Zero Alcohol on Weekdays | D16: 20-22 days | E16: Monday through Thursday | F16: Replace with sparkling mineral water with lime | G16: Preserves REM sleep cycles, liver recovery & cognitive clarity
A17: 11 | B17: Health & Fitness | C17: Eat Single-Ingredient Whole Foods | D17: 25-28 days | E17: All meals | F17: Weekly Sunday meal-prep session | G17: Stable blood glucose, zero sugar crashes & gut microbiome health
A18: 12 | B18: Health & Fitness | C18: Deep Breathing / Physiological Sigh | D18: 30 days | E18: Midday stress spike & bedtime | F18: Set watch haptic chime or transition cue | G18: Immediate autonomic down-regulation & heart-rate reduction
... A66: 60 | B66: Finance & Wealth | C66: Mindful Generosity / Tip Allocation | D66: 20-25 days | E66: Service interactions | F66: Add generous tip or donation with gratitude | G66: Breaks scarcity mentality and reinforces abundant wealth mindset
A68: ⚡ ATOMIC HABITS IMPLEMENTATION LAWS (BEHAVIORAL ARCHITECTURE)
A69: 1. The Habit Stacking Formula
A70: "After [CURRENT HABIT], I will [NEW HABIT] at [LOCATION]." Anchor new habits onto established neural wiring. Example: "After I pour my morning coffee, I will open my journal for 5 minutes at the kitchen counter."
A72: 2. The 2-Minute Rule
A73: "When you start a new habit, it should take less than two minutes to do." A habit must be established before it can be improved. Scale the gateway ritual down so low that failure is impossible (e.g. read 1 page; put on running shoes).
A75: 3. Environment Design
A76: "Make the cues of good habits obvious, and the cues of bad habits invisible." Environment is the invisible hand that shapes human behavior. Put the book on your pillow, the gym clothes in your doorway, and the phone charger in another room.
A78: 4. Never Miss Twice
A79: "Missing once is an accident. Missing twice is the start of a new bad habit." Perfection is impossible, but rapid recovery is non-negotiable. If you miss a day, prioritize getting a checkmark tomorrow even if it is only a 2-minute version.

Sheet Sep 2026
A1: 🏠 Master Dashboard | C1: 🏛️ Quarterly Hub | D1: 📚 Habit Library | E1: 2026 | F1: 2027 | G1: 2028 | H1: 2029 | I1: 2030 | J1: ◀ Prev | K1: Next ▶
A2: Habit Tracker | H2: "Win the morning, win the day." | AD2: @surajvansh
A3: September 2026 | H3: 30 Days Dashboard
A5: MONTHLY TARGETS
A6: 1. ____________________ : ____________________ | P6: 5. ____________________ : ____________________
A7: 2. ____________________ : ____________________ | P7: 6. ____________________ : ____________________
A8: 3. ____________________ : ____________________ | P8: 7. ____________________ : ____________________
A9: 4. ____________________ : ____________________ | P9: 8. ____________________ : ____________________
A11: NOTES:
A16: S.No. | B16: Protocols | C16: Category | D16: Target | E16: 1 | F16: 2 | G16: 3 | H16: 4 | I16: 5 | J16: 6 | K16: 7 | L16: 8 | M16: 9 | N16: 10 | O16: 11 | P16: 12 | Q16: 13 | R16: 14 | S16: 15 | T16: 16 | U16: 17 | V16: 18 | W16: 19 | X16: 20 | Y16: 21 | Z16: 22 | AA16: 23 | AB16: 24 | AC16: 25 | AD16: 26 | AE16: 27 | AF16: 28 | AG16: 29 | AH16: 30 | AI16: Success % | AJ16: Done / Target | AK16: Status | AL16: Done Count
E17: T | F17: W | G17: Th | H17: F | I17: Sa | J17: Su | K17: M | L17: T | M17: W | N17: Th | O17: F | P17: Sa | Q17: Su | R17: M | S17: T | T17: W | U17: Th | V17: F | W17: Sa | X17: Su | Y17: M | Z17: T | AA17: W | AB17: Th | AC17: F | AD17: Sa | AE17: Su | AF17: M | AG17: T | AH17: W
A18: 1 | AI18: =IF(ISBLANK(B18), "", IF(ISNUMBER(D18), IF(D18>0, (COUNTIF(E18:AH18, "✓") + COUNTIF(E18:AH18, "✔") + COUNTIF(E18:AH18, "v") + COUNTIF(E18:AH18, "V"))/D18, 0), IF(((COUNTIF(E18:AH18, "✓") + COUNTIF(E18:AH18, "✔") + COUNTIF(E18:AH18, "v") + COUNTIF(E18:AH18, "V")) + COUNTIF(E18:AH18, "✗") + COUNTIF(E18:AH18, "x") + COUNTIF(E18:AH18, "X"))>0, (COUNTIF(E18:AH18, "✓") + COUNTIF(E18:AH18, "✔") + COUNTIF(E18:AH18, "v") + COUNTIF(E18:AH18, "V"))/((COUNTIF(E18:AH18, "✓") + COUNTIF(E18:AH18, "✔") + COUNTIF(E18:AH18, "v") + COUNTIF(E18:AH18, "V")) + COUNTIF(E18:AH18, "✗") + COUNTIF(E18:AH18, "x") + COUNTIF(E18:AH18, "X")), ""))) | AJ18: =IF(ISBLANK(B18), "", IF(ISNUMBER(D18), IF(D18>0, (COUNTIF(E18:AH18, "✓") + COUNTIF(E18:AH18, "✔") + COUNTIF(E18:AH18, "v") + COUNTIF(E18:AH18, "V")) & "/" & D18, (COUNTIF(E18:AH18, "✓") + COUNTIF(E18:AH18, "✔") + COUNTIF(E18:AH18, "v") + COUNTIF(E18:AH18, "V")) & "/0"), IF(((COUNTIF(E18:AH18, "✓") + COUNTIF(E18:AH18, "✔") + COUNTIF(E18:AH18, "v") + COUNTIF(E18:AH18, "V")) + COUNTIF(E18:AH18, "✗") + COUNTIF(E18:AH18, "x") + COUNTIF(E18:AH18, "X"))>0, (COUNTIF(E18:AH18, "✓") + COUNTIF(E18:AH18, "✔") + COUNTIF(E18:AH18, "v") + COUNTIF(E18:AH18, "V")) & "/" & ((COUNTIF(E18:AH18, "✓") + COUNTIF(E18:AH18, "✔") + COUNTIF(E18:AH18, "v") + COUNTIF(E18:AH18, "V")) + COUNTIF(E18:AH18, "✗") + COUNTIF(E18:AH18, "x") + COUNTIF(E18:AH18, "X")), ""))) | AK18: =IF(ISBLANK(B18), "", IF(AI18>=0.85, "🔥 Mastered", IF(AI18>=0.7, "⚡ Consistent", "⚠️ Needs Focus"))) | AL18: =COUNTIF(E18:AH18, "✓")
A19: 2 | AI19: =IF(ISBLANK(B19), "", IF(ISNUMBER(D19), IF(D19>0, (COUNTIF(E19:AH19, "✓") + COUNTIF(E19:AH19, "✔") + COUNTIF(E19:AH19, "v") + COUNTIF(E19:AH19, "V"))/D19, 0), IF(((COUNTIF(E19:AH19, "✓") + COUNTIF(E19:AH19, "✔") + COUNTIF(E19:AH19, "v") + COUNTIF(E19:AH19, "V")) + COUNTIF(E19:AH19, "✗") + COUNTIF(E19:AH19, "x") + COUNTIF(E19:AH19, "X"))>0, (COUNTIF(E19:AH19, "✓") + COUNTIF(E19:AH19, "✔") + COUNTIF(E19:AH19, "v") + COUNTIF(E19:AH19, "V"))/((COUNTIF(E19:AH19, "✓") + COUNTIF(E19:AH19, "✔") + COUNTIF(E19:AH19, "v") + COUNTIF(E19:AH19, "V")) + COUNTIF(E19:AH19, "✗") + COUNTIF(E19:AH19, "x") + COUNTIF(E19:AH19, "X")), ""))) | AJ19: =IF(ISBLANK(B19), "", IF(ISNUMBER(D19), IF(D19>0, (COUNTIF(E19:AH19, "✓") + COUNTIF(E19:AH19, "✔") + COUNTIF(E19:AH19, "v") + COUNTIF(E19:AH19, "V")) & "/" & D19, (COUNTIF(E19:AH19, "✓") + COUNTIF(E19:AH19, "✔") + COUNTIF(E19:AH19, "v") + COUNTIF(E19:AH19, "V")) & "/0"), IF(((COUNTIF(E19:AH19, "✓") + COUNTIF(E19:AH19, "✔") + COUNTIF(E19:AH19, "v") + COUNTIF(E19:AH19, "V")) + COUNTIF(E19:AH19, "✗") + COUNTIF(E19:AH19, "x") + COUNTIF(E19:AH19, "X"))>0, (COUNTIF(E19:AH19, "✓") + COUNTIF(E19:AH19, "✔") + COUNTIF(E19:AH19, "v") + COUNTIF(E19:AH19, "V")) & "/" & ((COUNTIF(E19:AH19, "✓") + COUNTIF(E19:AH19, "✔") + COUNTIF(E19:AH19, "v") + COUNTIF(E19:AH19, "V")) + COUNTIF(E19:AH19, "✗") + COUNTIF(E19:AH19, "x") + COUNTIF(E19:AH19, "X")), ""))) | AK19: =IF(ISBLANK(B19), "", IF(AI19>=0.85, "🔥 Mastered", IF(AI19>=0.7, "⚡ Consistent", "⚠️ Needs Focus"))) | AL19: =COUNTIF(E19:AH19, "✓")
A20: 3 | AI20: =IF(ISBLANK(B20), "", IF(ISNUMBER(D20), IF(D20>0, (COUNTIF(E20:AH20, "✓") + COUNTIF(E20:AH20, "✔") + COUNTIF(E20:AH20, "v") + COUNTIF(E20:AH20, "V"))/D20, 0), IF(((COUNTIF(E20:AH20, "✓") + COUNTIF(E20:AH20, "✔") + COUNTIF(E20:AH20, "v") + COUNTIF(E20:AH20, "V")) + COUNTIF(E20:AH20, "✗") + COUNTIF(E20:AH20, "x") + COUNTIF(E20:AH20, "X"))>0, (COUNTIF(E20:AH20, "✓") + COUNTIF(E20:AH20, "✔") + COUNTIF(E20:AH20, "v") + COUNTIF(E20:AH20, "V"))/((COUNTIF(E20:AH20, "✓") + COUNTIF(E20:AH20, "✔") + COUNTIF(E20:AH20, "v") + COUNTIF(E20:AH20, "V")) + COUNTIF(E20:AH20, "✗") + COUNTIF(E20:AH20, "x") + COUNTIF(E20:AH20, "X")), ""))) | AJ20: =IF(ISBLANK(B20), "", IF(ISNUMBER(D20), IF(D20>0, (COUNTIF(E20:AH20, "✓") + COUNTIF(E20:AH20, "✔") + COUNTIF(E20:AH20, "v") + COUNTIF(E20:AH20, "V")) & "/" & D20, (COUNTIF(E20:AH20, "✓") + COUNTIF(E20:AH20, "✔") + COUNTIF(E20:AH20, "v") + COUNTIF(E20:AH20, "V")) & "/0"), IF(((COUNTIF(E20:AH20, "✓") + COUNTIF(E20:AH20, "✔") + COUNTIF(E20:AH20, "v") + COUNTIF(E20:AH20, "V")) + COUNTIF(E20:AH20, "✗") + COUNTIF(E20:AH20, "x") + COUNTIF(E20:AH20, "X"))>0, (COUNTIF(E20:AH20, "✓") + COUNTIF(E20:AH20, "✔") + COUNTIF(E20:AH20, "v") + COUNTIF(E20:AH20, "V")) & "/" & ((COUNTIF(E20:AH20, "✓") + COUNTIF(E20:AH20, "✔") + COUNTIF(E20:AH20, "v") + COUNTIF(E20:AH20, "V")) + COUNTIF(E20:AH20, "✗") + COUNTIF(E20:AH20, "x") + COUNTIF(E20:AH20, "X")), ""))) | AK20: =IF(ISBLANK(B20), "", IF(AI20>=0.85, "🔥 Mastered", IF(AI20>=0.7, "⚡ Consistent", "⚠️ Needs Focus"))) | AL20: =COUNTIF(E20:AH20, "✓")
A21: 4 | AI21: =IF(ISBLANK(B21), "", IF(ISNUMBER(D21), IF(D21>0, (COUNTIF(E21:AH21, "✓") + COUNTIF(E21:AH21, "✔") + COUNTIF(E21:AH21, "v") + COUNTIF(E21:AH21, "V"))/D21, 0), IF(((COUNTIF(E21:AH21, "✓") + COUNTIF(E21:AH21, "✔") + COUNTIF(E21:AH21, "v") + COUNTIF(E21:AH21, "V")) + COUNTIF(E21:AH21, "✗") + COUNTIF(E21:AH21, "x") + COUNTIF(E21:AH21, "X"))>0, (COUNTIF(E21:AH21, "✓") + COUNTIF(E21:AH21, "✔") + COUNTIF(E21:AH21, "v") + COUNTIF(E21:AH21, "V"))/((COUNTIF(E21:AH21, "✓") + COUNTIF(E21:AH21, "✔") + COUNTIF(E21:AH21, "v") + COUNTIF(E21:AH21, "V")) + COUNTIF(E21:AH21, "✗") + COUNTIF(E21:AH21, "x") + COUNTIF(E21:AH21, "X")), ""))) | AJ21: =IF(ISBLANK(B21), "", IF(ISNUMBER(D21), IF(D21>0, (COUNTIF(E21:AH21, "✓") + COUNTIF(E21:AH21, "✔") + COUNTIF(E21:AH21, "v") + COUNTIF(E21:AH21, "V")) & "/" & D21, (COUNTIF(E21:AH21, "✓") + COUNTIF(E21:AH21, "✔") + COUNTIF(E21:AH21, "v") + COUNTIF(E21:AH21, "V")) & "/0"), IF(((COUNTIF(E21:AH21, "✓") + COUNTIF(E21:AH21, "✔") + COUNTIF(E21:AH21, "v") + COUNTIF(E21:AH21, "V")) + COUNTIF(E21:AH21, "✗") + COUNTIF(E21:AH21, "x") + COUNTIF(E21:AH21, "X"))>0, (COUNTIF(E21:AH21, "✓") + COUNTIF(E21:AH21, "✔") + COUNTIF(E21:AH21, "v") + COUNTIF(E21:AH21, "V")) & "/" & ((COUNTIF(E21:AH21, "✓") + COUNTIF(E21:AH21, "✔") + COUNTIF(E21:AH21, "v") + COUNTIF(E21:AH21, "V")) + COUNTIF(E21:AH21, "✗") + COUNTIF(E21:AH21, "x") + COUNTIF(E21:AH21, "X")), ""))) | AK21: =IF(ISBLANK(B21), "", IF(AI21>=0.85, "🔥 Mastered", IF(AI21>=0.7, "⚡ Consistent", "⚠️ Needs Focus"))) | AL21: =COUNTIF(E21:AH21, "✓")
A22: 5 | AI22: =IF(ISBLANK(B22), "", IF(ISNUMBER(D22), IF(D22>0, (COUNTIF(E22:AH22, "✓") + COUNTIF(E22:AH22, "✔") + COUNTIF(E22:AH22, "v") + COUNTIF(E22:AH22, "V"))/D22, 0), IF(((COUNTIF(E22:AH22, "✓") + COUNTIF(E22:AH22, "✔") + COUNTIF(E22:AH22, "v") + COUNTIF(E22:AH22, "V")) + COUNTIF(E22:AH22, "✗") + COUNTIF(E22:AH22, "x") + COUNTIF(E22:AH22, "X"))>0, (COUNTIF(E22:AH22, "✓") + COUNTIF(E22:AH22, "✔") + COUNTIF(E22:AH22, "v") + COUNTIF(E22:AH22, "V"))/((COUNTIF(E22:AH22, "✓") + COUNTIF(E22:AH22, "✔") + COUNTIF(E22:AH22, "v") + COUNTIF(E22:AH22, "V")) + COUNTIF(E22:AH22, "✗") + COUNTIF(E22:AH22, "x") + COUNTIF(E22:AH22, "X")), ""))) | AJ22: =IF(ISBLANK(B22), "", IF(ISNUMBER(D22), IF(D22>0, (COUNTIF(E22:AH22, "✓") + COUNTIF(E22:AH22, "✔") + COUNTIF(E22:AH22, "v") + COUNTIF(E22:AH22, "V")) & "/" & D22, (COUNTIF(E22:AH22, "✓") + COUNTIF(E22:AH22, "✔") + COUNTIF(E22:AH22, "v") + COUNTIF(E22:AH22, "V")) & "/0"), IF(((COUNTIF(E22:AH22, "✓") + COUNTIF(E22:AH22, "✔") + COUNTIF(E22:AH22, "v") + COUNTIF(E22:AH22, "V")) + COUNTIF(E22:AH22, "✗") + COUNTIF(E22:AH22, "x") + COUNTIF(E22:AH22, "X"))>0, (COUNTIF(E22:AH22, "✓") + COUNTIF(E22:AH22, "✔") + COUNTIF(E22:AH22, "v") + COUNTIF(E22:AH22, "V")) & "/" & ((COUNTIF(E22:AH22, "✓") + COUNTIF(E22:AH22, "✔") + COUNTIF(E22:AH22, "v") + COUNTIF(E22:AH22, "V")) + COUNTIF(E22:AH22, "✗") + COUNTIF(E22:AH22, "x") + COUNTIF(E22:AH22, "X")), ""))) | AK22: =IF(ISBLANK(B22), "", IF(AI22>=0.85, "🔥 Mastered", IF(AI22>=0.7, "⚡ Consistent", "⚠️ Needs Focus"))) | AL22: =COUNTIF(E22:AH22, "✓")
A23: 6 | AI23: =IF(ISBLANK(B23), "", IF(ISNUMBER(D23), IF(D23>0, (COUNTIF(E23:AH23, "✓") + COUNTIF(E23:AH23, "✔") + COUNTIF(E23:AH23, "v") + COUNTIF(E23:AH23, "V"))/D23, 0), IF(((COUNTIF(E23:AH23, "✓") + COUNTIF(E23:AH23, "✔") + COUNTIF(E23:AH23, "v") + COUNTIF(E23:AH23, "V")) + COUNTIF(E23:AH23, "✗") + COUNTIF(E23:AH23, "x") + COUNTIF(E23:AH23, "X"))>0, (COUNTIF(E23:AH23, "✓") + COUNTIF(E23:AH23, "✔") + COUNTIF(E23:AH23, "v") + COUNTIF(E23:AH23, "V"))/((COUNTIF(E23:AH23, "✓") + COUNTIF(E23:AH23, "✔") + COUNTIF(E23:AH23, "v") + COUNTIF(E23:AH23, "V")) + COUNTIF(E23:AH23, "✗") + COUNTIF(E23:AH23, "x") + COUNTIF(E23:AH23, "X")), ""))) | AJ23: =IF(ISBLANK(B23), "", IF(ISNUMBER(D23), IF(D23>0, (COUNTIF(E23:AH23, "✓") + COUNTIF(E23:AH23, "✔") + COUNTIF(E23:AH23, "v") + COUNTIF(E23:AH23, "V")) & "/" & D23, (COUNTIF(E23:AH23, "✓") + COUNTIF(E23:AH23, "✔") + COUNTIF(E23:AH23, "v") + COUNTIF(E23:AH23, "V")) & "/0"), IF(((COUNTIF(E23:AH23, "✓") + COUNTIF(E23:AH23, "✔") + COUNTIF(E23:AH23, "v") + COUNTIF(E23:AH23, "V")) + COUNTIF(E23:AH23, "✗") + COUNTIF(E23:AH23, "x") + COUNTIF(E23:AH23, "X"))>0, (COUNTIF(E23:AH23, "✓") + COUNTIF(E23:AH23, "✔") + COUNTIF(E23:AH23, "v") + COUNTIF(E23:AH23, "V")) & "/" & ((COUNTIF(E23:AH23, "✓") + COUNTIF(E23:AH23, "✔") + COUNTIF(E23:AH23, "v") + COUNTIF(E23:AH23, "V")) + COUNTIF(E23:AH23, "✗") + COUNTIF(E23:AH23, "x") + COUNTIF(E23:AH23, "X")), ""))) | AK23: =IF(ISBLANK(B23), "", IF(AI23>=0.85, "🔥 Mastered", IF(AI23>=0.7, "⚡ Consistent", "⚠️ Needs Focus"))) | AL23: =COUNTIF(E23:AH23, "✓")
A24: 7 | AI24: =IF(ISBLANK(B24), "", IF(ISNUMBER(D24), IF(D24>0, (COUNTIF(E24:AH24, "✓") + COUNTIF(E24:AH24, "✔") + COUNTIF(E24:AH24, "v") + COUNTIF(E24:AH24, "V"))/D24, 0), IF(((COUNTIF(E24:AH24, "✓") + COUNTIF(E24:AH24, "✔") + COUNTIF(E24:AH24, "v") + COUNTIF(E24:AH24, "V")) + COUNTIF(E24:AH24, "✗") + COUNTIF(E24:AH24, "x") + COUNTIF(E24:AH24, "X"))>0, (COUNTIF(E24:AH24, "✓") + COUNTIF(E24:AH24, "✔") + COUNTIF(E24:AH24, "v") + COUNTIF(E24:AH24, "V"))/((COUNTIF(E24:AH24, "✓") + COUNTIF(E24:AH24, "✔") + COUNTIF(E24:AH24, "v") + COUNTIF(E24:AH24, "V")) + COUNTIF(E24:AH24, "✗") + COUNTIF(E24:AH24, "x") + COUNTIF(E24:AH24, "X")), ""))) | AJ24: =IF(ISBLANK(B24), "", IF(ISNUMBER(D24), IF(D24>0, (COUNTIF(E24:AH24, "✓") + COUNTIF(E24:AH24, "✔") + COUNTIF(E24:AH24, "v") + COUNTIF(E24:AH24, "V")) & "/" & D24, (COUNTIF(E24:AH24, "✓") + COUNTIF(E24:AH24, "✔") + COUNTIF(E24:AH24, "v") + COUNTIF(E24:AH24, "V")) & "/0"), IF(((COUNTIF(E24:AH24, "✓") + COUNTIF(E24:AH24, "✔") + COUNTIF(E24:AH24, "v") + COUNTIF(E24:AH24, "V")) + COUNTIF(E24:AH24, "✗") + COUNTIF(E24:AH24, "x") + COUNTIF(E24:AH24, "X"))>0, (COUNTIF(E24:AH24, "✓") + COUNTIF(E24:AH24, "✔") + COUNTIF(E24:AH24, "v") + COUNTIF(E24:AH24, "V")) & "/" & ((COUNTIF(E24:AH24, "✓") + COUNTIF(E24:AH24, "✔") + COUNTIF(E24:AH24, "v") + COUNTIF(E24:AH24, "V")) + COUNTIF(E24:AH24, "✗") + COUNTIF(E24:AH24, "x") + COUNTIF(E24:AH24, "X")), ""))) | AK24: =IF(ISBLANK(B24), "", IF(AI24>=0.85, "🔥 Mastered", IF(AI24>=0.7, "⚡ Consistent", "⚠️ Needs Focus"))) | AL24: =COUNTIF(E24:AH24, "✓")
A25: 8 | AI25: =IF(ISBLANK(B25), "", IF(ISNUMBER(D25), IF(D25>0, (COUNTIF(E25:AH25, "✓") + COUNTIF(E25:AH25, "✔") + COUNTIF(E25:AH25, "v") + COUNTIF(E25:AH25, "V"))/D25, 0), IF(((COUNTIF(E25:AH25, "✓") + COUNTIF(E25:AH25, "✔") + COUNTIF(E25:AH25, "v") + COUNTIF(E25:AH25, "V")) + COUNTIF(E25:AH25, "✗") + COUNTIF(E25:AH25, "x") + COUNTIF(E25:AH25, "X"))>0, (COUNTIF(E25:AH25, "✓") + COUNTIF(E25:AH25, "✔") + COUNTIF(E25:AH25, "v") + COUNTIF(E25:AH25, "V"))/((COUNTIF(E25:AH25, "✓") + COUNTIF(E25:AH25, "✔") + COUNTIF(E25:AH25, "v") + COUNTIF(E25:AH25, "V")) + COUNTIF(E25:AH25, "✗") + COUNTIF(E25:AH25, "x") + COUNTIF(E25:AH25, "X")), ""))) | AJ25: =IF(ISBLANK(B25), "", IF(ISNUMBER(D25), IF(D25>0, (COUNTIF(E25:AH25, "✓") + COUNTIF(E25:AH25, "✔") + COUNTIF(E25:AH25, "v") + COUNTIF(E25:AH25, "V")) & "/" & D25, (COUNTIF(E25:AH25, "✓") + COUNTIF(E25:AH25, "✔") + COUNTIF(E25:AH25, "v") + COUNTIF(E25:AH25, "V")) & "/0"), IF(((COUNTIF(E25:AH25, "✓") + COUNTIF(E25:AH25, "✔") + COUNTIF(E25:AH25, "v") + COUNTIF(E25:AH25, "V")) + COUNTIF(E25:AH25, "✗") + COUNTIF(E25:AH25, "x") + COUNTIF(E25:AH25, "X"))>0, (COUNTIF(E25:AH25, "✓") + COUNTIF(E25:AH25, "✔") + COUNTIF(E25:AH25, "v") + COUNTIF(E25:AH25, "V")) & "/" & ((COUNTIF(E25:AH25, "✓") + COUNTIF(E25:AH25, "✔") + COUNTIF(E25:AH25, "v") + COUNTIF(E25:AH25, "V")) + COUNTIF(E25:AH25, "✗") + COUNTIF(E25:AH25, "x") + COUNTIF(E25:AH25, "X")), ""))) | AK25: =IF(ISBLANK(B25), "", IF(AI25>=0.85, "🔥 Mastered", IF(AI25>=0.7, "⚡ Consistent", "⚠️ Needs Focus"))) | AL25: =COUNTIF(E25:AH25, "✓")
A26: 9 | AI26: =IF(ISBLANK(B26), "", IF(ISNUMBER(D26), IF(D26>0, (COUNTIF(E26:AH26, "✓") + COUNTIF(E26:AH26, "✔") + COUNTIF(E26:AH26, "v") + COUNTIF(E26:AH26, "V"))/D26, 0), IF(((COUNTIF(E26:AH26, "✓") + COUNTIF(E26:AH26, "✔") + COUNTIF(E26:AH26, "v") + COUNTIF(E26:AH26, "V")) + COUNTIF(E26:AH26, "✗") + COUNTIF(E26:AH26, "x") + COUNTIF(E26:AH26, "X"))>0, (COUNTIF(E26:AH26, "✓") + COUNTIF(E26:AH26, "✔") + COUNTIF(E26:AH26, "v") + COUNTIF(E26:AH26, "V"))/((COUNTIF(E26:AH26, "✓") + COUNTIF(E26:AH26, "✔") + COUNTIF(E26:AH26, "v") + COUNTIF(E26:AH26, "V")) + COUNTIF(E26:AH26, "✗") + COUNTIF(E26:AH26, "x") + COUNTIF(E26:AH26, "X")), ""))) | AJ26: =IF(ISBLANK(B26), "", IF(ISNUMBER(D26), IF(D26>0, (COUNTIF(E26:AH26, "✓") + COUNTIF(E26:AH26, "✔") + COUNTIF(E26:AH26, "v") + COUNTIF(E26:AH26, "V")) & "/" & D26, (COUNTIF(E26:AH26, "✓") + COUNTIF(E26:AH26, "✔") + COUNTIF(E26:AH26, "v") + COUNTIF(E26:AH26, "V")) & "/0"), IF(((COUNTIF(E26:AH26, "✓") + COUNTIF(E26:AH26, "✔") + COUNTIF(E26:AH26, "v") + COUNTIF(E26:AH26, "V")) + COUNTIF(E26:AH26, "✗") + COUNTIF(E26:AH26, "x") + COUNTIF(E26:AH26, "X"))>0, (COUNTIF(E26:AH26, "✓") + COUNTIF(E26:AH26, "✔") + COUNTIF(E26:AH26, "v") + COUNTIF(E26:AH26, "V")) & "/" & ((COUNTIF(E26:AH26, "✓") + COUNTIF(E26:AH26, "✔") + COUNTIF(E26:AH26, "v") + COUNTIF(E26:AH26, "V")) + COUNTIF(E26:AH26, "✗") + COUNTIF(E26:AH26, "x") + COUNTIF(E26:AH26, "X")), ""))) | AK26: =IF(ISBLANK(B26), "", IF(AI26>=0.85, "🔥 Mastered", IF(AI26>=0.7, "⚡ Consistent", "⚠️ Needs Focus"))) | AL26: =COUNTIF(E26:AH26, "✓")
A27: 10 | AI27: =IF(ISBLANK(B27), "", IF(ISNUMBER(D27), IF(D27>0, (COUNTIF(E27:AH27, "✓") + COUNTIF(E27:AH27, "✔") + COUNTIF(E27:AH27, "v") + COUNTIF(E27:AH27, "V"))/D27, 0), IF(((COUNTIF(E27:AH27, "✓") + COUNTIF(E27:AH27, "✔") + COUNTIF(E27:AH27, "v") + COUNTIF(E27:AH27, "V")) + COUNTIF(E27:AH27, "✗") + COUNTIF(E27:AH27, "x") + COUNTIF(E27:AH27, "X"))>0, (COUNTIF(E27:AH27, "✓") + COUNTIF(E27:AH27, "✔") + COUNTIF(E27:AH27, "v") + COUNTIF(E27:AH27, "V"))/((COUNTIF(E27:AH27, "✓") + COUNTIF(E27:AH27, "✔") + COUNTIF(E27:AH27, "v") + COUNTIF(E27:AH27, "V")) + COUNTIF(E27:AH27, "✗") + COUNTIF(E27:AH27, "x") + COUNTIF(E27:AH27, "X")), ""))) | AJ27: =IF(ISBLANK(B27), "", IF(ISNUMBER(D27), IF(D27>0, (COUNTIF(E27:AH27, "✓") + COUNTIF(E27:AH27, "✔") + COUNTIF(E27:AH27, "v") + COUNTIF(E27:AH27, "V")) & "/" & D27, (COUNTIF(E27:AH27, "✓") + COUNTIF(E27:AH27, "✔") + COUNTIF(E27:AH27, "v") + COUNTIF(E27:AH27, "V")) & "/0"), IF(((COUNTIF(E27:AH27, "✓") + COUNTIF(E27:AH27, "✔") + COUNTIF(E27:AH27, "v") + COUNTIF(E27:AH27, "V")) + COUNTIF(E27:AH27, "✗") + COUNTIF(E27:AH27, "x") + COUNTIF(E27:AH27, "X"))>0, (COUNTIF(E27:AH27, "✓") + COUNTIF(E27:AH27, "✔") + COUNTIF(E27:AH27, "v") + COUNTIF(E27:AH27, "V")) & "/" & ((COUNTIF(E27:AH27, "✓") + COUNTIF(E27:AH27, "✔") + COUNTIF(E27:AH27, "v") + COUNTIF(E27:AH27, "V")) + COUNTIF(E27:AH27, "✗") + COUNTIF(E27:AH27, "x") + COUNTIF(E27:AH27, "X")), ""))) | AK27: =IF(ISBLANK(B27), "", IF(AI27>=0.85, "🔥 Mastered", IF(AI27>=0.7, "⚡ Consistent", "⚠️ Needs Focus"))) | AL27: =COUNTIF(E27:AH27, "✓")
A28: 11 | AI28: =IF(ISBLANK(B28), "", IF(ISNUMBER(D28), IF(D28>0, (COUNTIF(E28:AH28, "✓") + COUNTIF(E28:AH28, "✔") + COUNTIF(E28:AH28, "v") + COUNTIF(E28:AH28, "V"))/D28, 0), IF(((COUNTIF(E28:AH28, "✓") + COUNTIF(E28:AH28, "✔") + COUNTIF(E28:AH28, "v") + COUNTIF(E28:AH28, "V")) + COUNTIF(E28:AH28, "✗") + COUNTIF(E28:AH28, "x") + COUNTIF(E28:AH28, "X"))>0, (COUNTIF(E28:AH28, "✓") + COUNTIF(E28:AH28, "✔") + COUNTIF(E28:AH28, "v") + COUNTIF(E28:AH28, "V"))/((COUNTIF(E28:AH28, "✓") + COUNTIF(E28:AH28, "✔") + COUNTIF(E28:AH28, "v") + COUNTIF(E28:AH28, "V")) + COUNTIF(E28:AH28, "✗") + COUNTIF(E28:AH28, "x") + COUNTIF(E28:AH28, "X")), ""))) | AJ28: =IF(ISBLANK(B28), "", IF(ISNUMBER(D28), IF(D28>0, (COUNTIF(E28:AH28, "✓") + COUNTIF(E28:AH28, "✔") + COUNTIF(E28:AH28, "v") + COUNTIF(E28:AH28, "V")) & "/" & D28, (COUNTIF(E28:AH28, "✓") + COUNTIF(E28:AH28, "✔") + COUNTIF(E28:AH28, "v") + COUNTIF(E28:AH28, "V")) & "/0"), IF(((COUNTIF(E28:AH28, "✓") + COUNTIF(E28:AH28, "✔") + COUNTIF(E28:AH28, "v") + COUNTIF(E28:AH28, "V")) + COUNTIF(E28:AH28, "✗") + COUNTIF(E28:AH28, "x") + COUNTIF(E28:AH28, "X"))>0, (COUNTIF(E28:AH28, "✓") + COUNTIF(E28:AH28, "✔") + COUNTIF(E28:AH28, "v") + COUNTIF(E28:AH28, "V")) & "/" & ((COUNTIF(E28:AH28, "✓") + COUNTIF(E28:AH28, "✔") + COUNTIF(E28:AH28, "v") + COUNTIF(E28:AH28, "V")) + COUNTIF(E28:AH28, "✗") + COUNTIF(E28:AH28, "x") + COUNTIF(E28:AH28, "X")), ""))) | AK28: =IF(ISBLANK(B28), "", IF(AI28>=0.85, "🔥 Mastered", IF(AI28>=0.7, "⚡ Consistent", "⚠️ Needs Focus"))) | AL28: =COUNTIF(E28:AH28, "✓")
A29: 12 | AI29: =IF(ISBLANK(B29), "", IF(ISNUMBER(D29), IF(D29>0, (COUNTIF(E29:AH29, "✓") + COUNTIF(E29:AH29, "✔") + COUNTIF(E29:AH29, "v") + COUNTIF(E29:AH29, "V"))/D29, 0), IF(((COUNTIF(E29:AH29, "✓") + COUNTIF(E29:AH29, "✔") + COUNTIF(E29:AH29, "v") + COUNTIF(E29:AH29, "V")) + COUNTIF(E29:AH29, "✗") + COUNTIF(E29:AH29, "x") + COUNTIF(E29:AH29, "X"))>0, (COUNTIF(E29:AH29, "✓") + COUNTIF(E29:AH29, "✔") + COUNTIF(E29:AH29, "v") + COUNTIF(E29:AH29, "V"))/((COUNTIF(E29:AH29, "✓") + COUNTIF(E29:AH29, "✔") + COUNTIF(E29:AH29, "v") + COUNTIF(E29:AH29, "V")) + COUNTIF(E29:AH29, "✗") + COUNTIF(E29:AH29, "x") + COUNTIF(E29:AH29, "X")), ""))) | AJ29: =IF(ISBLANK(B29), "", IF(ISNUMBER(D29), IF(D29>0, (COUNTIF(E29:AH29, "✓") + COUNTIF(E29:AH29, "✔") + COUNTIF(E29:AH29, "v") + COUNTIF(E29:AH29, "V")) & "/" & D29, (COUNTIF(E29:AH29, "✓") + COUNTIF(E29:AH29, "✔") + COUNTIF(E29:AH29, "v") + COUNTIF(E29:AH29, "V")) & "/0"), IF(((COUNTIF(E29:AH29, "✓") + COUNTIF(E29:AH29, "✔") + COUNTIF(E29:AH29, "v") + COUNTIF(E29:AH29, "V")) + COUNTIF(E29:AH29, "✗") + COUNTIF(E29:AH29, "x") + COUNTIF(E29:AH29, "X"))>0, (COUNTIF(E29:AH29, "✓") + COUNTIF(E29:AH29, "✔") + COUNTIF(E29:AH29, "v") + COUNTIF(E29:AH29, "V")) & "/" & ((COUNTIF(E29:AH29, "✓") + COUNTIF(E29:AH29, "✔") + COUNTIF(E29:AH29, "v") + COUNTIF(E29:AH29, "V")) + COUNTIF(E29:AH29, "✗") + COUNTIF(E29:AH29, "x") + COUNTIF(E29:AH29, "X")), ""))) | AK29: =IF(ISBLANK(B29), "", IF(AI29>=0.85, "🔥 Mastered", IF(AI29>=0.7, "⚡ Consistent", "⚠️ Needs Focus"))) | AL29: =COUNTIF(E29:AH29, "✓")
... A37: 20 | AI37: =IF(ISBLANK(B37), "", IF(ISNUMBER(D37), IF(D37>0, (COUNTIF(E37:AH37, "✓") + COUNTIF(E37:AH37, "✔") + COUNTIF(E37:AH37, "v") + COUNTIF(E37:AH37, "V"))/D37, 0), IF(((COUNTIF(E37:AH37, "✓") + COUNTIF(E37:AH37, "✔") + COUNTIF(E37:AH37, "v") + COUNTIF(E37:AH37, "V")) + COUNTIF(E37:AH37, "✗") + COUNTIF(E37:AH37, "x") + COUNTIF(E37:AH37, "X"))>0, (COUNTIF(E37:AH37, "✓") + COUNTIF(E37:AH37, "✔") + COUNTIF(E37:AH37, "v") + COUNTIF(E37:AH37, "V"))/((COUNTIF(E37:AH37, "✓") + COUNTIF(E37:AH37, "✔") + COUNTIF(E37:AH37, "v") + COUNTIF(E37:AH37, "V")) + COUNTIF(E37:AH37, "✗") + COUNTIF(E37:AH37, "x") + COUNTIF(E37:AH37, "X")), ""))) | AJ37: =IF(ISBLANK(B37), "", IF(ISNUMBER(D37), IF(D37>0, (COUNTIF(E37:AH37, "✓") + COUNTIF(E37:AH37, "✔") + COUNTIF(E37:AH37, "v") + COUNTIF(E37:AH37, "V")) & "/" & D37, (COUNTIF(E37:AH37, "✓") + COUNTIF(E37:AH37, "✔") + COUNTIF(E37:AH37, "v") + COUNTIF(E37:AH37, "V")) & "/0"), IF(((COUNTIF(E37:AH37, "✓") + COUNTIF(E37:AH37, "✔") + COUNTIF(E37:AH37, "v") + COUNTIF(E37:AH37, "V")) + COUNTIF(E37:AH37, "✗") + COUNTIF(E37:AH37, "x") + COUNTIF(E37:AH37, "X"))>0, (COUNTIF(E37:AH37, "✓") + COUNTIF(E37:AH37, "✔") + COUNTIF(E37:AH37, "v") + COUNTIF(E37:AH37, "V")) & "/" & ((COUNTIF(E37:AH37, "✓") + COUNTIF(E37:AH37, "✔") + COUNTIF(E37:AH37, "v") + COUNTIF(E37:AH37, "V")) + COUNTIF(E37:AH37, "✗") + COUNTIF(E37:AH37, "x") + COUNTIF(E37:AH37, "X")), ""))) | AK37: =IF(ISBLANK(B37), "", IF(AI37>=0.85, "🔥 Mastered", IF(AI37>=0.7, "⚡ Consistent", "⚠️ Needs Focus"))) | AL37: =COUNTIF(E37:AH37, "✓")
A38: DAILY TOTAL SCORE | E38: =IF(((COUNTIF(E18:E37, "✓") + COUNTIF(E18:E37, "✔") + COUNTIF(E18:E37, "v") + COUNTIF(E18:E37, "V")) + COUNTIF(E18:E37, "✗") + COUNTIF(E18:E37, "x") + COUNTIF(E18:E37, "X")) > 0, (COUNTIF(E18:E37, "✓") + COUNTIF(E18:E37, "✔") + COUNTIF(E18:E37, "v") + COUNTIF(E18:E37, "V")) & "/" & ((COUNTIF(E18:E37, "✓") + COUNTIF(E18:E37, "✔") + COUNTIF(E18:E37, "v") + COUNTIF(E18:E37, "V")) + COUNTIF(E18:E37, "✗") + COUNTIF(E18:E37, "x") + COUNTIF(E18:E37, "X")), "") | F38: =IF(((COUNTIF(F18:F37, "✓") + COUNTIF(F18:F37, "✔") + COUNTIF(F18:F37, "v") + COUNTIF(F18:F37, "V")) + COUNTIF(F18:F37, "✗") + COUNTIF(F18:F37, "x") + COUNTIF(F18:F37, "X")) > 0, (COUNTIF(F18:F37, "✓") + COUNTIF(F18:F37, "✔") + COUNTIF(F18:F37, "v") + COUNTIF(F18:F37, "V")) & "/" & ((COUNTIF(F18:F37, "✓") + COUNTIF(F18:F37, "✔") + COUNTIF(F18:F37, "v") + COUNTIF(F18:F37, "V")) + COUNTIF(F18:F37, "✗") + COUNTIF(F18:F37, "x") + COUNTIF(F18:F37, "X")), "") | G38: =IF(((COUNTIF(G18:G37, "✓") + COUNTIF(G18:G37, "✔") + COUNTIF(G18:G37, "v") + COUNTIF(G18:G37, "V")) + COUNTIF(G18:G37, "✗") + COUNTIF(G18:G37, "x") + COUNTIF(G18:G37, "X")) > 0, (COUNTIF(G18:G37, "✓") + COUNTIF(G18:G37, "✔") + COUNTIF(G18:G37, "v") + COUNTIF(G18:G37, "V")) & "/" & ((COUNTIF(G18:G37, "✓") + COUNTIF(G18:G37, "✔") + COUNTIF(G18:G37, "v") + COUNTIF(G18:G37, "V")) + COUNTIF(G18:G37, "✗") + COUNTIF(G18:G37, "x") + COUNTIF(G18:G37, "X")), "") | H38: =IF(((COUNTIF(H18:H37, "✓") + COUNTIF(H18:H37, "✔") + COUNTIF(H18:H37, "v") + COUNTIF(H18:H37, "V")) + COUNTIF(H18:H37, "✗") + COUNTIF(H18:H37, "x") + COUNTIF(H18:H37, "X")) > 0, (COUNTIF(H18:H37, "✓") + COUNTIF(H18:H37, "✔") + COUNTIF(H18:H37, "v") + COUNTIF(H18:H37, "V")) & "/" & ((COUNTIF(H18:H37, "✓") + COUNTIF(H18:H37, "✔") + COUNTIF(H18:H37, "v") + COUNTIF(H18:H37, "V")) + COUNTIF(H18:H37, "✗") + COUNTIF(H18:H37, "x") + COUNTIF(H18:H37, "X")), "") | I38: =IF(((COUNTIF(I18:I37, "✓") + COUNTIF(I18:I37, "✔") + COUNTIF(I18:I37, "v") + COUNTIF(I18:I37, "V")) + COUNTIF(I18:I37, "✗") + COUNTIF(I18:I37, "x") + COUNTIF(I18:I37, "X")) > 0, (COUNTIF(I18:I37, "✓") + COUNTIF(I18:I37, "✔") + COUNTIF(I18:I37, "v") + COUNTIF(I18:I37, "V")) & "/" & ((COUNTIF(I18:I37, "✓") + COUNTIF(I18:I37, "✔") + COUNTIF(I18:I37, "v") + COUNTIF(I18:I37, "V")) + COUNTIF(I18:I37, "✗") + COUNTIF(I18:I37, "x") + COUNTIF(I18:I37, "X")), "") | J38: =IF(((COUNTIF(J18:J37, "✓") + COUNTIF(J18:J37, "✔") + COUNTIF(J18:J37, "v") + COUNTIF(J18:J37, "V")) + COUNTIF(J18:J37, "✗") + COUNTIF(J18:J37, "x") + COUNTIF(J18:J37, "X")) > 0, (COUNTIF(J18:J37, "✓") + COUNTIF(J18:J37, "✔") + COUNTIF(J18:J37, "v") + COUNTIF(J18:J37, "V")) & "/" & ((COUNTIF(J18:J37, "✓") + COUNTIF(J18:J37, "✔") + COUNTIF(J18:J37, "v") + COUNTIF(J18:J37, "V")) + COUNTIF(J18:J37, "✗") + COUNTIF(J18:J37, "x") + COUNTIF(J18:J37, "X")), "") | K38: =IF(((COUNTIF(K18:K37, "✓") + COUNTIF(K18:K37, "✔") + COUNTIF(K18:K37, "v") + COUNTIF(K18:K37, "V")) + COUNTIF(K18:K37, "✗") + COUNTIF(K18:K37, "x") + COUNTIF(K18:K37, "X")) > 0, (COUNTIF(K18:K37, "✓") + COUNTIF(K18:K37, "✔") + COUNTIF(K18:K37, "v") + COUNTIF(K18:K37, "V")) & "/" & ((COUNTIF(K18:K37, "✓") + COUNTIF(K18:K37, "✔") + COUNTIF(K18:K37, "v") + COUNTIF(K18:K37, "V")) + COUNTIF(K18:K37, "✗") + COUNTIF(K18:K37, "x") + COUNTIF(K18:K37, "X")), "") | L38: =IF(((COUNTIF(L18:L37, "✓") + COUNTIF(L18:L37, "✔") + COUNTIF(L18:L37, "v") + COUNTIF(L18:L37, "V")) + COUNTIF(L18:L37, "✗") + COUNTIF(L18:L37, "x") + COUNTIF(L18:L37, "X")) > 0, (COUNTIF(L18:L37, "✓") + COUNTIF(L18:L37, "✔") + COUNTIF(L18:L37, "v") + COUNTIF(L18:L37, "V")) & "/" & ((COUNTIF(L18:L37, "✓") + COUNTIF(L18:L37, "✔") + COUNTIF(L18:L37, "v") + COUNTIF(L18:L37, "V")) + COUNTIF(L18:L37, "✗") + COUNTIF(L18:L37, "x") + COUNTIF(L18:L37, "X")), "") | ... AH38: =IF(((COUNTIF(AH18:AH37, "✓") + COUNTIF(AH18:AH37, "✔") + COUNTIF(AH18:AH37, "v") + COUNTIF(AH18:AH37, "V")) + COUNTIF(AH18:AH37, "✗") + COUNTIF(AH18:AH37, "x") + COUNTIF(AH18:AH37, "X")) > 0, (COUNTIF(AH18:AH37, "✓") + COUNTIF(AH18:AH37, "✔") + COUNTIF(AH18:AH37, "v") + COUNTIF(AH18:AH37, "V")) & "/" & ((COUNTIF(AH18:AH37, "✓") + COUNTIF(AH18:AH37, "✔") + COUNTIF(AH18:AH37, "v") + COUNTIF(AH18:AH37, "V")) + COUNTIF(AH18:AH37, "✗") + COUNTIF(AH18:AH37, "x") + COUNTIF(AH18:AH37, "X")), "") | AI38: =IF(SUM(D18:D37) > 0, SUM(AL18:AL37) / SUM(D18:D37), "") | AJ38: =IF(SUM(D18:D37) > 0, SUM(AL18:AL37) & "/" & SUM(D18:D37), "")
A39: DAILY SUCCESS % | E39: =IF(((COUNTIF(E18:E37, "✓") + COUNTIF(E18:E37, "✔") + COUNTIF(E18:E37, "v") + COUNTIF(E18:E37, "V")) + COUNTIF(E18:E37, "✗") + COUNTIF(E18:E37, "x") + COUNTIF(E18:E37, "X")) > 0, (COUNTIF(E18:E37, "✓") + COUNTIF(E18:E37, "✔") + COUNTIF(E18:E37, "v") + COUNTIF(E18:E37, "V")) / ((COUNTIF(E18:E37, "✓") + COUNTIF(E18:E37, "✔") + COUNTIF(E18:E37, "v") + COUNTIF(E18:E37, "V")) + COUNTIF(E18:E37, "✗") + COUNTIF(E18:E37, "x") + COUNTIF(E18:E37, "X")), "") | F39: =IF(((COUNTIF(F18:F37, "✓") + COUNTIF(F18:F37, "✔") + COUNTIF(F18:F37, "v") + COUNTIF(F18:F37, "V")) + COUNTIF(F18:F37, "✗") + COUNTIF(F18:F37, "x") + COUNTIF(F18:F37, "X")) > 0, (COUNTIF(F18:F37, "✓") + COUNTIF(F18:F37, "✔") + COUNTIF(F18:F37, "v") + COUNTIF(F18:F37, "V")) / ((COUNTIF(F18:F37, "✓") + COUNTIF(F18:F37, "✔") + COUNTIF(F18:F37, "v") + COUNTIF(F18:F37, "V")) + COUNTIF(F18:F37, "✗") + COUNTIF(F18:F37, "x") + COUNTIF(F18:F37, "X")), "") | G39: =IF(((COUNTIF(G18:G37, "✓") + COUNTIF(G18:G37, "✔") + COUNTIF(G18:G37, "v") + COUNTIF(G18:G37, "V")) + COUNTIF(G18:G37, "✗") + COUNTIF(G18:G37, "x") + COUNTIF(G18:G37, "X")) > 0, (COUNTIF(G18:G37, "✓") + COUNTIF(G18:G37, "✔") + COUNTIF(G18:G37, "v") + COUNTIF(G18:G37, "V")) / ((COUNTIF(G18:G37, "✓") + COUNTIF(G18:G37, "✔") + COUNTIF(G18:G37, "v") + COUNTIF(G18:G37, "V")) + COUNTIF(G18:G37, "✗") + COUNTIF(G18:G37, "x") + COUNTIF(G18:G37, "X")), "") | H39: =IF(((COUNTIF(H18:H37, "✓") + COUNTIF(H18:H37, "✔") + COUNTIF(H18:H37, "v") + COUNTIF(H18:H37, "V")) + COUNTIF(H18:H37, "✗") + COUNTIF(H18:H37, "x") + COUNTIF(H18:H37, "X")) > 0, (COUNTIF(H18:H37, "✓") + COUNTIF(H18:H37, "✔") + COUNTIF(H18:H37, "v") + COUNTIF(H18:H37, "V")) / ((COUNTIF(H18:H37, "✓") + COUNTIF(H18:H37, "✔") + COUNTIF(H18:H37, "v") + COUNTIF(H18:H37, "V")) + COUNTIF(H18:H37, "✗") + COUNTIF(H18:H37, "x") + COUNTIF(H18:H37, "X")), "") | I39: =IF(((COUNTIF(I18:I37, "✓") + COUNTIF(I18:I37, "✔") + COUNTIF(I18:I37, "v") + COUNTIF(I18:I37, "V")) + COUNTIF(I18:I37, "✗") + COUNTIF(I18:I37, "x") + COUNTIF(I18:I37, "X")) > 0, (COUNTIF(I18:I37, "✓") + COUNTIF(I18:I37, "✔") + COUNTIF(I18:I37, "v") + COUNTIF(I18:I37, "V")) / ((COUNTIF(I18:I37, "✓") + COUNTIF(I18:I37, "✔") + COUNTIF(I18:I37, "v") + COUNTIF(I18:I37, "V")) + COUNTIF(I18:I37, "✗") + COUNTIF(I18:I37, "x") + COUNTIF(I18:I37, "X")), "") | J39: =IF(((COUNTIF(J18:J37, "✓") + COUNTIF(J18:J37, "✔") + COUNTIF(J18:J37, "v") + COUNTIF(J18:J37, "V")) + COUNTIF(J18:J37, "✗") + COUNTIF(J18:J37, "x") + COUNTIF(J18:J37, "X")) > 0, (COUNTIF(J18:J37, "✓") + COUNTIF(J18:J37, "✔") + COUNTIF(J18:J37, "v") + COUNTIF(J18:J37, "V")) / ((COUNTIF(J18:J37, "✓") + COUNTIF(J18:J37, "✔") + COUNTIF(J18:J37, "v") + COUNTIF(J18:J37, "V")) + COUNTIF(J18:J37, "✗") + COUNTIF(J18:J37, "x") + COUNTIF(J18:J37, "X")), "") | K39: =IF(((COUNTIF(K18:K37, "✓") + COUNTIF(K18:K37, "✔") + COUNTIF(K18:K37, "v") + COUNTIF(K18:K37, "V")) + COUNTIF(K18:K37, "✗") + COUNTIF(K18:K37, "x") + COUNTIF(K18:K37, "X")) > 0, (COUNTIF(K18:K37, "✓") + COUNTIF(K18:K37, "✔") + COUNTIF(K18:K37, "v") + COUNTIF(K18:K37, "V")) / ((COUNTIF(K18:K37, "✓") + COUNTIF(K18:K37, "✔") + COUNTIF(K18:K37, "v") + COUNTIF(K18:K37, "V")) + COUNTIF(K18:K37, "✗") + COUNTIF(K18:K37, "x") + COUNTIF(K18:K37, "X")), "") | L39: =IF(((COUNTIF(L18:L37, "✓") + COUNTIF(L18:L37, "✔") + COUNTIF(L18:L37, "v") + COUNTIF(L18:L37, "V")) + COUNTIF(L18:L37, "✗") + COUNTIF(L18:L37, "x") + COUNTIF(L18:L37, "X")) > 0, (COUNTIF(L18:L37, "✓") + COUNTIF(L18:L37, "✔") + COUNTIF(L18:L37, "v") + COUNTIF(L18:L37, "V")) / ((COUNTIF(L18:L37, "✓") + COUNTIF(L18:L37, "✔") + COUNTIF(L18:L37, "v") + COUNTIF(L18:L37, "V")) + COUNTIF(L18:L37, "✗") + COUNTIF(L18:L37, "x") + COUNTIF(L18:L37, "X")), "") | ... AH39: =IF(((COUNTIF(AH18:AH37, "✓") + COUNTIF(AH18:AH37, "✔") + COUNTIF(AH18:AH37, "v") + COUNTIF(AH18:AH37, "V")) + COUNTIF(AH18:AH37, "✗") + COUNTIF(AH18:AH37, "x") + COUNTIF(AH18:AH37, "X")) > 0, (COUNTIF(AH18:AH37, "✓") + COUNTIF(AH18:AH37, "✔") + COUNTIF(AH18:AH37, "v") + COUNTIF(AH18:AH37, "V")) / ((COUNTIF(AH18:AH37, "✓") + COUNTIF(AH18:AH37, "✔") + COUNTIF(AH18:AH37, "v") + COUNTIF(AH18:AH37, "V")) + COUNTIF(AH18:AH37, "✗") + COUNTIF(AH18:AH37, "x") + COUNTIF(AH18:AH37, "X")), "") | AI39: =IF(COUNT(E39:AH39) > 0, AVERAGE(E39:AH39), "")
A41: IF SUCCESS < 80%, PUNISHMENT: ________________________________________________
A42: IF SUCCESS > 90%, REWARD: __________________________________________________
A45: Sleep Tracking | E45: 1 | F45: 2 | G45: 3 | H45: 4 | I45: 5 | J45: 6 | K45: 7 | L45: 8 | M45: 9 | N45: 10 | O45: 11 | P45: 12 | Q45: 13 | R45: 14 | S45: 15 | T45: 16 | U45: 17 | V45: 18 | W45: 19 | X45: 20 | Y45: 21 | Z45: 22 | AA45: 23 | AB45: 24 | AC45: 25 | AD45: 26 | AE45: 27 | AF45: 28 | AG45: 29 | AH45: 30
E46: T | F46: W | G46: Th | H46: F | I46: Sa | J46: Su | K46: M | L46: T | M46: W | N46: Th | O46: F | P46: Sa | Q46: Su | R46: M | S46: T | T46: W | U46: Th | V46: F | W46: Sa | X46: Su | Y46: M | Z46: T | AA46: W | AB46: Th | AC46: F | AD46: Sa | AE46: Su | AF46: M | AG46: T | AH46: W
A47: Sleep Hours (1-24)
A67: MONTHLY SUCCESS RATE | F67: ACTIVE PROTOCOLS | K67: PERFECT DAYS (100%) | P67: AVG SLEEP DURATION
A68: =IF(SUM(D18:D37)>0, SUM(AL18:AL37)/SUM(D18:D37), 0) | F68: =COUNTA(B18:B37) & " / 20" | K68: =COUNTIF(E39:AH39, 1) & " Days" | P68: =IFERROR(TEXT(AVERAGE(E47:AH47), "0.0") & " hrs", "-")
A71: Target Completion | F71: Habits Tracked | K71: All Marked Habits Completed | P71: Nightly Rest Average
A74: WEEKLY PERFORMANCE (SLUMP DETECTOR) | N74: LIFE DOMAIN / CATEGORY BREAKDOWN
A75: Week | B75: Days Range | C75: Checks Done | D75: Evaluated | E75: Success % | N75: Domain / Category | P75: Active Habits | Q75: Target Days | R75: Done Checks | S75: Success %
A76: Week 1 | B76: Days 1 - 7 | C76: =COUNTIF(E18:K37, "✓") | D76: =COUNTIF(E18:K37, "✓") + COUNTIF(E18:K37, "✗") | E76: =IFERROR(C76/D76, 0) | N76: Health & Fitness | P76: =COUNTIF($C$18:$C$37, "Health & Fitness") | Q76: =SUMIF($C$18:$C$37, "Health & Fitness", $D$18:$D$37) | R76: =SUMIF($C$18:$C$37, "Health & Fitness", $AL$18:$AL$37) | S76: =IFERROR(R76/Q76, 0)
A77: Week 2 | B77: Days 8 - 14 | C77: =COUNTIF(L18:R37, "✓") | D77: =COUNTIF(L18:R37, "✓") + COUNTIF(L18:R37, "✗") | E77: =IFERROR(C77/D77, 0) | N77: Mindset & Learning | P77: =COUNTIF($C$18:$C$37, "Mindset & Learning") | Q77: =SUMIF($C$18:$C$37, "Mindset & Learning", $D$18:$D$37) | R77: =SUMIF($C$18:$C$37, "Mindset & Learning", $AL$18:$AL$37) | S77: =IFERROR(R77/Q77, 0)
A78: Week 3 | B78: Days 15 - 21 | C78: =COUNTIF(S18:Y37, "✓") | D78: =COUNTIF(S18:Y37, "✓") + COUNTIF(S18:Y37, "✗") | E78: =IFERROR(C78/D78, 0) | N78: Career & Focus | P78: =COUNTIF($C$18:$C$37, "Career & Focus") | Q78: =SUMIF($C$18:$C$37, "Career & Focus", $D$18:$D$37) | R78: =SUMIF($C$18:$C$37, "Career & Focus", $AL$18:$AL$37) | S78: =IFERROR(R78/Q78, 0)
A79: Week 4 | B79: Days 22 - 28 | C79: =COUNTIF(Z18:AF37, "✓") | D79: =COUNTIF(Z18:AF37, "✓") + COUNTIF(Z18:AF37, "✗") | E79: =IFERROR(C79/D79, 0) | N79: Personal & Home | P79: =COUNTIF($C$18:$C$37, "Personal & Home") | Q79: =SUMIF($C$18:$C$37, "Personal & Home", $D$18:$D$37) | R79: =SUMIF($C$18:$C$37, "Personal & Home", $AL$18:$AL$37) | S79: =IFERROR(R79/Q79, 0)
...

Sheet Oct 2026
A1: 🏠 Master Dashboard | C1: 🏛️ Quarterly Hub | D1: 📚 Habit Library | E1: 2026 | F1: 2027 | G1: 2028 | H1: 2029 | I1: 2030 | J1: ◀ Prev | K1: Next ▶
A2: Habit Tracker | H2: "Discipline equals freedom." | AE2: @surajvansh
A3: October 2026 | H3: 31 Days Dashboard
A5: MONTHLY TARGETS
A6: 1. ____________________ : ____________________ | P6: 5. ____________________ : ____________________
A7: 2. ____________________ : ____________________ | P7: 6. ____________________ : ____________________
A8: 3. ____________________ : ____________________ | P8: 7. ____________________ : ____________________
A9: 4. ____________________ : ____________________ | P9: 8. ____________________ : ____________________
A11: NOTES:
A16: S.No. | B16: Protocols | C16: Category | D16: Target | E16: 1 | F16: 2 | G16: 3 | H16: 4 | I16: 5 | J16: 6 | K16: 7 | L16: 8 | M16: 9 | N16: 10 | O16: 11 | P16: 12 | Q16: 13 | R16: 14 | S16: 15 | T16: 16 | U16: 17 | V16: 18 | W16: 19 | X16: 20 | Y16: 21 | Z16: 22 | AA16: 23 | AB16: 24 | AC16: 25 | AD16: 26 | AE16: 27 | AF16: 28 | AG16: 29 | AH16: 30 | AI16: 31 | AJ16: Success % | AK16: Done / Target | AL16: Status | AM16: Done Count
E17: Th | F17: F | G17: Sa | H17: Su | I17: M | J17: T | K17: W | L17: Th | M17: F | N17: Sa | O17: Su | P17: M | Q17: T | R17: W | S17: Th | T17: F | U17: Sa | V17: Su | W17: M | X17: T | Y17: W | Z17: Th | AA17: F | AB17: Sa | AC17: Su | AD17: M | AE17: T | AF17: W | AG17: Th | AH17: F | AI17: Sa
A18: 1 | AJ18: =IF(ISBLANK(B18), "", IF(ISNUMBER(D18), IF(D18>0, (COUNTIF(E18:AI18, "✓") + COUNTIF(E18:AI18, "✔") + COUNTIF(E18:AI18, "v") + COUNTIF(E18:AI18, "V"))/D18, 0), IF(((COUNTIF(E18:AI18, "✓") + COUNTIF(E18:AI18, "✔") + COUNTIF(E18:AI18, "v") + COUNTIF(E18:AI18, "V")) + COUNTIF(E18:AI18, "✗") + COUNTIF(E18:AI18, "x") + COUNTIF(E18:AI18, "X"))>0, (COUNTIF(E18:AI18, "✓") + COUNTIF(E18:AI18, "✔") + COUNTIF(E18:AI18, "v") + COUNTIF(E18:AI18, "V"))/((COUNTIF(E18:AI18, "✓") + COUNTIF(E18:AI18, "✔") + COUNTIF(E18:AI18, "v") + COUNTIF(E18:AI18, "V")) + COUNTIF(E18:AI18, "✗") + COUNTIF(E18:AI18, "x") + COUNTIF(E18:AI18, "X")), ""))) | AK18: =IF(ISBLANK(B18), "", IF(ISNUMBER(D18), IF(D18>0, (COUNTIF(E18:AI18, "✓") + COUNTIF(E18:AI18, "✔") + COUNTIF(E18:AI18, "v") + COUNTIF(E18:AI18, "V")) & "/" & D18, (COUNTIF(E18:AI18, "✓") + COUNTIF(E18:AI18, "✔") + COUNTIF(E18:AI18, "v") + COUNTIF(E18:AI18, "V")) & "/0"), IF(((COUNTIF(E18:AI18, "✓") + COUNTIF(E18:AI18, "✔") + COUNTIF(E18:AI18, "v") + COUNTIF(E18:AI18, "V")) + COUNTIF(E18:AI18, "✗") + COUNTIF(E18:AI18, "x") + COUNTIF(E18:AI18, "X"))>0, (COUNTIF(E18:AI18, "✓") + COUNTIF(E18:AI18, "✔") + COUNTIF(E18:AI18, "v") + COUNTIF(E18:AI18, "V")) & "/" & ((COUNTIF(E18:AI18, "✓") + COUNTIF(E18:AI18, "✔") + COUNTIF(E18:AI18, "v") + COUNTIF(E18:AI18, "V")) + COUNTIF(E18:AI18, "✗") + COUNTIF(E18:AI18, "x") + COUNTIF(E18:AI18, "X")), ""))) | AL18: =IF(ISBLANK(B18), "", IF(AJ18>=0.85, "🔥 Mastered", IF(AJ18>=0.7, "⚡ Consistent", "⚠️ Needs Focus"))) | AM18: =COUNTIF(E18:AI18, "✓")
A19: 2 | AJ19: =IF(ISBLANK(B19), "", IF(ISNUMBER(D19), IF(D19>0, (COUNTIF(E19:AI19, "✓") + COUNTIF(E19:AI19, "✔") + COUNTIF(E19:AI19, "v") + COUNTIF(E19:AI19, "V"))/D19, 0), IF(((COUNTIF(E19:AI19, "✓") + COUNTIF(E19:AI19, "✔") + COUNTIF(E19:AI19, "v") + COUNTIF(E19:AI19, "V")) + COUNTIF(E19:AI19, "✗") + COUNTIF(E19:AI19, "x") + COUNTIF(E19:AI19, "X"))>0, (COUNTIF(E19:AI19, "✓") + COUNTIF(E19:AI19, "✔") + COUNTIF(E19:AI19, "v") + COUNTIF(E19:AI19, "V"))/((COUNTIF(E19:AI19, "✓") + COUNTIF(E19:AI19, "✔") + COUNTIF(E19:AI19, "v") + COUNTIF(E19:AI19, "V")) + COUNTIF(E19:AI19, "✗") + COUNTIF(E19:AI19, "x") + COUNTIF(E19:AI19, "X")), ""))) | AK19: =IF(ISBLANK(B19), "", IF(ISNUMBER(D19), IF(D19>0, (COUNTIF(E19:AI19, "✓") + COUNTIF(E19:AI19, "✔") + COUNTIF(E19:AI19, "v") + COUNTIF(E19:AI19, "V")) & "/" & D19, (COUNTIF(E19:AI19, "✓") + COUNTIF(E19:AI19, "✔") + COUNTIF(E19:AI19, "v") + COUNTIF(E19:AI19, "V")) & "/0"), IF(((COUNTIF(E19:AI19, "✓") + COUNTIF(E19:AI19, "✔") + COUNTIF(E19:AI19, "v") + COUNTIF(E19:AI19, "V")) + COUNTIF(E19:AI19, "✗") + COUNTIF(E19:AI19, "x") + COUNTIF(E19:AI19, "X"))>0, (COUNTIF(E19:AI19, "✓") + COUNTIF(E19:AI19, "✔") + COUNTIF(E19:AI19, "v") + COUNTIF(E19:AI19, "V")) & "/" & ((COUNTIF(E19:AI19, "✓") + COUNTIF(E19:AI19, "✔") + COUNTIF(E19:AI19, "v") + COUNTIF(E19:AI19, "V")) + COUNTIF(E19:AI19, "✗") + COUNTIF(E19:AI19, "x") + COUNTIF(E19:AI19, "X")), ""))) | AL19: =IF(ISBLANK(B19), "", IF(AJ19>=0.85, "🔥 Mastered", IF(AJ19>=0.7, "⚡ Consistent", "⚠️ Needs Focus"))) | AM19: =COUNTIF(E19:AI19, "✓")
A20: 3 | AJ20: =IF(ISBLANK(B20), "", IF(ISNUMBER(D20), IF(D20>0, (COUNTIF(E20:AI20, "✓") + COUNTIF(E20:AI20, "✔") + COUNTIF(E20:AI20, "v") + COUNTIF(E20:AI20, "V"))/D20, 0), IF(((COUNTIF(E20:AI20, "✓") + COUNTIF(E20:AI20, "✔") + COUNTIF(E20:AI20, "v") + COUNTIF(E20:AI20, "V")) + COUNTIF(E20:AI20, "✗") + COUNTIF(E20:AI20, "x") + COUNTIF(E20:AI20, "X"))>0, (COUNTIF(E20:AI20, "✓") + COUNTIF(E20:AI20, "✔") + COUNTIF(E20:AI20, "v") + COUNTIF(E20:AI20, "V"))/((COUNTIF(E20:AI20, "✓") + COUNTIF(E20:AI20, "✔") + COUNTIF(E20:AI20, "v") + COUNTIF(E20:AI20, "V")) + COUNTIF(E20:AI20, "✗") + COUNTIF(E20:AI20, "x") + COUNTIF(E20:AI20, "X")), ""))) | AK20: =IF(ISBLANK(B20), "", IF(ISNUMBER(D20), IF(D20>0, (COUNTIF(E20:AI20, "✓") + COUNTIF(E20:AI20, "✔") + COUNTIF(E20:AI20, "v") + COUNTIF(E20:AI20, "V")) & "/" & D20, (COUNTIF(E20:AI20, "✓") + COUNTIF(E20:AI20, "✔") + COUNTIF(E20:AI20, "v") + COUNTIF(E20:AI20, "V")) & "/0"), IF(((COUNTIF(E20:AI20, "✓") + COUNTIF(E20:AI20, "✔") + COUNTIF(E20:AI20, "v") + COUNTIF(E20:AI20, "V")) + COUNTIF(E20:AI20, "✗") + COUNTIF(E20:AI20, "x") + COUNTIF(E20:AI20, "X"))>0, (COUNTIF(E20:AI20, "✓") + COUNTIF(E20:AI20, "✔") + COUNTIF(E20:AI20, "v") + COUNTIF(E20:AI20, "V")) & "/" & ((COUNTIF(E20:AI20, "✓") + COUNTIF(E20:AI20, "✔") + COUNTIF(E20:AI20, "v") + COUNTIF(E20:AI20, "V")) + COUNTIF(E20:AI20, "✗") + COUNTIF(E20:AI20, "x") + COUNTIF(E20:AI20, "X")), ""))) | AL20: =IF(ISBLANK(B20), "", IF(AJ20>=0.85, "🔥 Mastered", IF(AJ20>=0.7, "⚡ Consistent", "⚠️ Needs Focus"))) | AM20: =COUNTIF(E20:AI20, "✓")
